[2019-04-02 15:09:39,248: INFO/MainProcess] Connected to redis://localhost:6379/0
[2019-04-02 15:09:39,260: INFO/MainProcess] mingle: searching for neighbors
[2019-04-02 15:09:40,292: INFO/MainProcess] mingle: all alone
[2019-04-02 15:09:40,324: WARNING/MainProcess] /usr/local/lib/python3.7/site-packages/celery/fixups/django.py:200: UserWarning: Using settings.DEBUG leads to a memory leak, never use this setting in production environments!
  warnings.warn('Using settings.DEBUG leads to a memory leak, never '
[2019-04-02 15:09:40,324: INFO/MainProcess] w1@macbook.local ready.
[2019-04-02 15:12:09,089: INFO/MainProcess] sync with celery@macbook.local
[2019-04-02 15:23:59,746: WARNING/MainProcess] Substantial drift from celery@macbook.local may mean clocks are out of sync.  Current drift is
18000 seconds.  [orig: 2019-04-02 15:23:59.745478 recv: 2019-04-02 10:23:59.742080]

[2019-04-02 15:23:59,767: INFO/MainProcess] sync with celery@macbook.local
[2019-04-02 15:29:15,711: WARNING/MainProcess] consumer: Connection to broker lost. Trying to re-establish the connection...
Traceback (most recent call last):
  File "/usr/local/lib/python3.7/site-packages/redis/connection.py", line 185, in _read_from_socket
    raise socket.error(SERVER_CLOSED_CONNECTION_ERROR)
OSError: Connection closed by server.

During handling of the above exception, another exception occurred:

Traceback (most recent call last):
  File "/usr/local/lib/python3.7/site-packages/celery/worker/consumer/consumer.py", line 317, in start
    blueprint.start(self)
  File "/usr/local/lib/python3.7/site-packages/celery/bootsteps.py", line 119, in start
    step.start(parent)
  File "/usr/local/lib/python3.7/site-packages/celery/worker/consumer/consumer.py", line 593, in start
    c.loop(*c.loop_args())
  File "/usr/local/lib/python3.7/site-packages/celery/worker/loops.py", line 91, in asynloop
    next(loop)
  File "/usr/local/lib/python3.7/site-packages/kombu/asynchronous/hub.py", line 362, in create_loop
    cb(*cbargs)
  File "/usr/local/lib/python3.7/site-packages/kombu/transport/redis.py", line 1065, in on_readable
    self.cycle.on_readable(fileno)
  File "/usr/local/lib/python3.7/site-packages/kombu/transport/redis.py", line 348, in on_readable
    chan.handlers[type]()
  File "/usr/local/lib/python3.7/site-packages/kombu/transport/redis.py", line 725, in _brpop_read
    **options)
  File "/usr/local/lib/python3.7/site-packages/redis/client.py", line 789, in parse_response
    response = connection.read_response()
  File "/usr/local/lib/python3.7/site-packages/redis/connection.py", line 637, in read_response
    response = self._parser.read_response()
  File "/usr/local/lib/python3.7/site-packages/redis/connection.py", line 290, in read_response
    response = self._buffer.readline()
  File "/usr/local/lib/python3.7/site-packages/redis/connection.py", line 224, in readline
    self._read_from_socket()
  File "/usr/local/lib/python3.7/site-packages/redis/connection.py", line 199, in _read_from_socket
    (e.args,))
redis.exceptions.ConnectionError: Error while reading from socket: ('Connection closed by server.',)
[2019-04-02 15:29:15,792: ERROR/MainProcess] consumer: Cannot connect to redis://localhost:6379/0: Error 61 connecting to localhost:6379. Connection refused..
Trying again in 2.00 seconds...

[2019-04-02 15:29:17,798: ERROR/MainProcess] consumer: Cannot connect to redis://localhost:6379/0: Error 61 connecting to localhost:6379. Connection refused..
Trying again in 4.00 seconds...

[2019-04-02 15:29:21,816: ERROR/MainProcess] consumer: Cannot connect to redis://localhost:6379/0: Error 61 connecting to localhost:6379. Connection refused..
Trying again in 6.00 seconds...

[2019-04-02 15:29:28,433: ERROR/MainProcess] consumer: Cannot connect to redis://localhost:6379/0: Error 61 connecting to localhost:6379. Connection refused..
Trying again in 8.00 seconds...

[2019-04-02 15:29:36,463: ERROR/MainProcess] consumer: Cannot connect to redis://localhost:6379/0: Error 61 connecting to localhost:6379. Connection refused..
Trying again in 10.00 seconds...

[2019-04-02 15:29:46,489: ERROR/MainProcess] consumer: Cannot connect to redis://localhost:6379/0: Error 61 connecting to localhost:6379. Connection refused..
Trying again in 12.00 seconds...

[2019-04-02 15:29:58,526: ERROR/MainProcess] consumer: Cannot connect to redis://localhost:6379/0: Error 61 connecting to localhost:6379. Connection refused..
Trying again in 14.00 seconds...

[2019-04-02 15:30:12,572: INFO/MainProcess] Connected to redis://localhost:6379/0
[2019-04-02 15:30:12,574: CRITICAL/MainProcess] Unrecoverable error: KeyError(30)
Traceback (most recent call last):
  File "/usr/local/lib/python3.7/site-packages/celery/worker/worker.py", line 205, in start
    self.blueprint.start(self)
  File "/usr/local/lib/python3.7/site-packages/celery/bootsteps.py", line 119, in start
    step.start(parent)
  File "/usr/local/lib/python3.7/site-packages/celery/bootsteps.py", line 369, in start
    return self.obj.start()
  File "/usr/local/lib/python3.7/site-packages/celery/worker/consumer/consumer.py", line 317, in start
    blueprint.start(self)
  File "/usr/local/lib/python3.7/site-packages/celery/bootsteps.py", line 119, in start
    step.start(parent)
  File "/usr/local/lib/python3.7/site-packages/celery/worker/consumer/events.py", line 37, in start
    prev = self._close(c)
  File "/usr/local/lib/python3.7/site-packages/celery/worker/consumer/events.py", line 63, in _close
    ignore_errors(c, dispatcher.connection.close)
  File "/usr/local/lib/python3.7/site-packages/kombu/common.py", line 295, in ignore_errors
    return fun(*args, **kwargs)
  File "/usr/local/lib/python3.7/site-packages/kombu/connection.py", line 372, in release
    self._close()
  File "/usr/local/lib/python3.7/site-packages/kombu/connection.py", line 338, in _close
    self._do_close_self()
  File "/usr/local/lib/python3.7/site-packages/kombu/connection.py", line 328, in _do_close_self
    self.maybe_close_channel(self._default_channel)
  File "/usr/local/lib/python3.7/site-packages/kombu/connection.py", line 320, in maybe_close_channel
    channel.close()
  File "/usr/local/lib/python3.7/site-packages/kombu/transport/redis.py", line 852, in close
    self._disconnect_pools()
  File "/usr/local/lib/python3.7/site-packages/kombu/transport/redis.py", line 538, in _disconnect_pools
    async_pool.disconnect()
  File "/usr/local/lib/python3.7/site-packages/redis/connection.py", line 1041, in disconnect
    connection.disconnect()
  File "/usr/local/lib/python3.7/site-packages/kombu/transport/redis.py", line 941, in disconnect
    channel._on_connection_disconnect(self)
  File "/usr/local/lib/python3.7/site-packages/kombu/transport/redis.py", line 546, in _on_connection_disconnect
    self.connection.cycle._on_connection_disconnect(connection)
  File "/usr/local/lib/python3.7/site-packages/kombu/transport/redis.py", line 282, in _on_connection_disconnect
    self.poller.unregister(connection._sock)
  File "/usr/local/lib/python3.7/site-packages/kombu/utils/eventio.py", line 209, in unregister
    self._quick_unregister(fd)
KeyError: 30
